Workbook

Sheet ตารางหลัก
A1: ตารางแข่งขันแบบเข้าฐาน (Battle Rally) — 16 ทีม / 8 ฐาน / 8 รอบ
A2: แถว = รอบ, คอลัมน์ = ฐาน, แต่ละช่อง = คู่ที่แบทเทิลกัน
A4: รอบ | B4: ฐาน 1 | C4: ฐาน 2 | D4: ฐาน 3 | E4: ฐาน 4 | F4: ฐาน 5 | G4: ฐาน 6 | H4: ฐาน 7 | I4: ฐาน 8
A5: รอบ 1 | B5: 6B vs 7A | C5: 1A vs 5B | D5: 4B vs 7B | E5: 1B vs 6A | F5: 2A vs 5A | G5: 2B vs 8A | H5: 3A vs 4A | I5: 3B vs 8B
A6: รอบ 2 | B6: 4B vs 5B | C6: 5A vs 6A | D6: 1A vs 3A | E6: 2B vs 6B | F6: 1B vs 8B | G6: 4A vs 7B | H6: 2A vs 3B | I6: 7A vs 8A
A7: รอบ 3 | B7: 3A vs 5A | C7: 7A vs 8B | D7: 1B vs 3B | E7: 2A vs 4A | F7: 1A vs 6B | G7: 5B vs 6A | H7: 4B vs 8A | I7: 2B vs 7B
A8: รอบ 4 | B8: 3B vs 4A | C8: 7B vs 8A | D8: 5A vs 8B | E8: 4B vs 7A | F8: 2B vs 5B | G8: 1B vs 2A | H8: 1A vs 6A | I8: 3A vs 6B
A9: รอบ 5 | B9: 7B vs 8B | C9: 2A vs 4B | D9: 2B vs 7A | E9: 3A vs 5B | F9: 6A vs 8A | G9: 1A vs 3B | H9: 1B vs 6B | I9: 4A vs 5A
A10: รอบ 6 | B10: 1B vs 2B | C10: 3B vs 6B | D10: 4A vs 6A | E10: 5A vs 8A | F10: 3A vs 7B | G10: 4B vs 8B | H10: 5B vs 7A | I10: 1A vs 2A
A11: รอบ 7 | B11: 2A vs 6A | C11: 2B vs 4A | D11: 6B vs 8A | E11: 1A vs 8B | F11: 3B vs 4B | G11: 3A vs 7A | H11: 5A vs 7B | I11: 1B vs 5B
A12: รอบ 8 | B12: 1A vs 8A | C12: 1B vs 3A | D12: 2A vs 5B | E12: 3B vs 7B | F12: 4A vs 7A | G12: 5A vs 6B | H12: 2B vs 8B | I12: 4B vs 6A
A14: เงื่อนไขที่ตารางนี้ทำได้ครบ: (1) ทุกฐานมี 2 ทีมทุกรอบ (2) แต่ละทีมเข้าครบ 8 ฐาน ฐานละครั้ง (3) ไม่มีคู่ซ้ำ (4) ไม่มีคู่จากกลุ่มเดียวกัน

Sheet ตารางรายทีม
A1: ตารางรายทีม (สำหรับแจกแต่ละทีม)
A3: ทีม | B3: รอบ 1 | C3: รอบ 2 | D3: รอบ 3 | E3: รอบ 4 | F3: รอบ 5 | G3: รอบ 6 | H3: รอบ 7 | I3: รอบ 8
A4: 1A | B4: ฐาน 2 (พบ 5B) | C4: ฐาน 3 (พบ 3A) | D4: ฐาน 5 (พบ 6B) | E4: ฐาน 7 (พบ 6A) | F4: ฐาน 6 (พบ 3B) | G4: ฐาน 8 (พบ 2A) | H4: ฐาน 4 (พบ 8B) | I4: ฐาน 1 (พบ 8A)
A5: 1B | B5: ฐาน 4 (พบ 6A) | C5: ฐาน 5 (พบ 8B) | D5: ฐาน 3 (พบ 3B) | E5: ฐาน 6 (พบ 2A) | F5: ฐาน 7 (พบ 6B) | G5: ฐาน 1 (พบ 2B) | H5: ฐาน 8 (พบ 5B) | I5: ฐาน 2 (พบ 3A)
A6: 2A | B6: ฐาน 5 (พบ 5A) | C6: ฐาน 7 (พบ 3B) | D6: ฐาน 4 (พบ 4A) | E6: ฐาน 6 (พบ 1B) | F6: ฐาน 2 (พบ 4B) | G6: ฐาน 8 (พบ 1A) | H6: ฐาน 1 (พบ 6A) | I6: ฐาน 3 (พบ 5B)
A7: 2B | B7: ฐาน 6 (พบ 8A) | C7: ฐาน 4 (พบ 6B) | D7: ฐาน 8 (พบ 7B) | E7: ฐาน 5 (พบ 5B) | F7: ฐาน 3 (พบ 7A) | G7: ฐาน 1 (พบ 1B) | H7: ฐาน 2 (พบ 4A) | I7: ฐาน 7 (พบ 8B)
A8: 3A | B8: ฐาน 7 (พบ 4A) | C8: ฐาน 3 (พบ 1A) | D8: ฐาน 1 (พบ 5A) | E8: ฐาน 8 (พบ 6B) | F8: ฐาน 4 (พบ 5B) | G8: ฐาน 5 (พบ 7B) | H8: ฐาน 6 (พบ 7A) | I8: ฐาน 2 (พบ 1B)
A9: 3B | B9: ฐาน 8 (พบ 8B) | C9: ฐาน 7 (พบ 2A) | D9: ฐาน 3 (พบ 1B) | E9: ฐาน 1 (พบ 4A) | F9: ฐาน 6 (พบ 1A) | G9: ฐาน 2 (พบ 6B) | H9: ฐาน 5 (พบ 4B) | I9: ฐาน 4 (พบ 7B)
A10: 4A | B10: ฐาน 7 (พบ 3A) | C10: ฐาน 6 (พบ 7B) | D10: ฐาน 4 (พบ 2A) | E10: ฐาน 1 (พบ 3B) | F10: ฐาน 8 (พบ 5A) | G10: ฐาน 3 (พบ 6A) | H10: ฐาน 2 (พบ 2B) | I10: ฐาน 5 (พบ 7A)
A11: 4B | B11: ฐาน 3 (พบ 7B) | C11: ฐาน 1 (พบ 5B) | D11: ฐาน 7 (พบ 8A) | E11: ฐาน 4 (พบ 7A) | F11: ฐาน 2 (พบ 2A) | G11: ฐาน 6 (พบ 8B) | H11: ฐาน 5 (พบ 3B) | I11: ฐาน 8 (พบ 6A)
A12: 5A | B12: ฐาน 5 (พบ 2A) | C12: ฐาน 2 (พบ 6A) | D12: ฐาน 1 (พบ 3A) | E12: ฐาน 3 (พบ 8B) | F12: ฐาน 8 (พบ 4A) | G12: ฐาน 4 (พบ 8A) | H12: ฐาน 7 (พบ 7B) | I12: ฐาน 6 (พบ 6B)
A13: 5B | B13: ฐาน 2 (พบ 1A) | C13: ฐาน 1 (พบ 4B) | D13: ฐาน 6 (พบ 6A) | E13: ฐาน 5 (พบ 2B) | F13: ฐาน 4 (พบ 3A) | G13: ฐาน 7 (พบ 7A) | H13: ฐาน 8 (พบ 1B) | I13: ฐาน 3 (พบ 2A)
A14: 6A | B14: ฐาน 4 (พบ 1B) | C14: ฐาน 2 (พบ 5A) | D14: ฐาน 6 (พบ 5B) | E14: ฐาน 7 (พบ 1A) | F14: ฐาน 5 (พบ 8A) | G14: ฐาน 3 (พบ 4A) | H14: ฐาน 1 (พบ 2A) | I14: ฐาน 8 (พบ 4B)
... A19: 8B | B19: ฐาน 8 (พบ 3B) | C19: ฐาน 5 (พบ 1B) | D19: ฐาน 2 (พบ 7A) | E19: ฐาน 3 (พบ 5A) | F19: ฐาน 1 (พบ 7B) | G19: ฐาน 6 (พบ 4B) | H19: ฐาน 4 (พบ 1A) | I19: ฐาน 7 (พบ 2B)

Sheet ใบคุมประจำฐาน
A1: ใบบันทึกผลประจำฐาน (พิมพ์แจกกรรมการแต่ละฐาน)
A2: ช่องสีเหลือง = ช่องที่กรรมการกรอก
A4: ฐานที่ 1
A5: รอบ | B5: ทีม 1 | C5: ทีม 2 | D5: คะแนนทีม 1 | E5: คะแนนทีม 2 | F5: ทีมที่ชนะ
A6: รอบ 1 | B6: 6B | C6: 7A
A7: รอบ 2 | B7: 4B | C7: 5B
A8: รอบ 3 | B8: 3A | C8: 5A
A9: รอบ 4 | B9: 3B | C9: 4A
A10: รอบ 5 | B10: 7B | C10: 8B
A11: รอบ 6 | B11: 1B | C11: 2B
A12: รอบ 7 | B12: 2A | C12: 6A
A13: รอบ 8 | B13: 1A | C13: 8A
A15: ฐานที่ 2
A16: รอบ | B16: ทีม 1 | C16: ทีม 2 | D16: คะแนนทีม 1 | E16: คะแนนทีม 2 | F16: ทีมที่ชนะ
A17: รอบ 1 | B17: 1A | C17: 5B
A18: รอบ 2 | B18: 5A | C18: 6A
A19: รอบ 3 | B19: 7A | C19: 8B
A20: รอบ 4 | B20: 7B | C20: 8A
A21: รอบ 5 | B21: 2A | C21: 4B
A22: รอบ 6 | B22: 3B | C22: 6B
A23: รอบ 7 | B23: 2B | C23: 4A
A24: รอบ 8 | B24: 1B | C24: 3A
A26: ฐานที่ 3
A27: รอบ | B27: ทีม 1 | C27: ทีม 2 | D27: คะแนนทีม 1 | E27: คะแนนทีม 2 | F27: ทีมที่ชนะ
A28: รอบ 1 | B28: 4B | C28: 7B
A29: รอบ 2 | B29: 1A | C29: 3A
A30: รอบ 3 | B30: 1B | C30: 3B
A31: รอบ 4 | B31: 5A | C31: 8B
A32: รอบ 5 | B32: 2B | C32: 7A
A33: รอบ 6 | B33: 4A | C33: 6A
A34: รอบ 7 | B34: 6B | C34: 8A
A35: รอบ 8 | B35: 2A | C35: 5B
A37: ฐานที่ 4
A38: รอบ | B38: ทีม 1 | C38: ทีม 2 | D38: คะแนนทีม 1 | E38: คะแนนทีม 2 | F38: ทีมที่ชนะ
A39: รอบ 1 | B39: 1B | C39: 6A
A40: รอบ 2 | B40: 2B | C40: 6B
A41: รอบ 3 | B41: 2A | C41: 4A
A42: รอบ 4 | B42: 4B | C42: 7A
A43: รอบ 5 | B43: 3A | C43: 5B
A44: รอบ 6 | B44: 5A | C44: 8A
...

Sheet ข้อมูลดิบ
A1: รอบ | B1: ฐาน | C1: ทีม1 | D1: ทีม2 | E1: คีย์คู่ | F1: กลุ่มเดียวกัน(1=ผิด)
A2: 1 | B2: 1 | C2: 6B | D2: 7A | E2: =IF(C2<D2,C2&"-"&D2,D2&"-"&C2) -> 6B-7A | F2: =IF(LEFT(C2,1)=LEFT(D2,1),1,0) -> 0
A3: 1 | B3: 2 | C3: 1A | D3: 5B | E3: =IF(C3<D3,C3&"-"&D3,D3&"-"&C3) -> 1A-5B | F3: =IF(LEFT(C3,1)=LEFT(D3,1),1,0) -> 0
A4: 1 | B4: 3 | C4: 4B | D4: 7B | E4: =IF(C4<D4,C4&"-"&D4,D4&"-"&C4) -> 4B-7B | F4: =IF(LEFT(C4,1)=LEFT(D4,1),1,0) -> 0
A5: 1 | B5: 4 | C5: 1B | D5: 6A | E5: =IF(C5<D5,C5&"-"&D5,D5&"-"&C5) -> 1B-6A | F5: =IF(LEFT(C5,1)=LEFT(D5,1),1,0) -> 0
A6: 1 | B6: 5 | C6: 2A | D6: 5A | E6: =IF(C6<D6,C6&"-"&D6,D6&"-"&C6) -> 2A-5A | F6: =IF(LEFT(C6,1)=LEFT(D6,1),1,0) -> 0
A7: 1 | B7: 6 | C7: 2B | D7: 8A | E7: =IF(C7<D7,C7&"-"&D7,D7&"-"&C7) -> 2B-8A | F7: =IF(LEFT(C7,1)=LEFT(D7,1),1,0) -> 0
A8: 1 | B8: 7 | C8: 3A | D8: 4A | E8: =IF(C8<D8,C8&"-"&D8,D8&"-"&C8) -> 3A-4A | F8: =IF(LEFT(C8,1)=LEFT(D8,1),1,0) -> 0
A9: 1 | B9: 8 | C9: 3B | D9: 8B | E9: =IF(C9<D9,C9&"-"&D9,D9&"-"&C9) -> 3B-8B | F9: =IF(LEFT(C9,1)=LEFT(D9,1),1,0) -> 0
A10: 2 | B10: 1 | C10: 4B | D10: 5B | E10: =IF(C10<D10,C10&"-"&D10,D10&"-"&C10) -> 4B-5B | F10: =IF(LEFT(C10,1)=LEFT(D10,1),1,0) -> 0
A11: 2 | B11: 2 | C11: 5A | D11: 6A | E11: =IF(C11<D11,C11&"-"&D11,D11&"-"&C11) -> 5A-6A | F11: =IF(LEFT(C11,1)=LEFT(D11,1),1,0) -> 0
A12: 2 | B12: 3 | C12: 1A | D12: 3A | E12: =IF(C12<D12,C12&"-"&D12,D12&"-"&C12) -> 1A-3A | F12: =IF(LEFT(C12,1)=LEFT(D12,1),1,0) -> 0
A13: 2 | B13: 4 | C13: 2B | D13: 6B | E13: =IF(C13<D13,C13&"-"&D13,D13&"-"&C13) -> 2B-6B | F13: =IF(LEFT(C13,1)=LEFT(D13,1),1,0) -> 0
... A65: 8 | B65: 8 | C65: 4B | D65: 6A | E65: =IF(C65<D65,C65&"-"&D65,D65&"-"&C65) -> 4B-6A | F65: =IF(LEFT(C65,1)=LEFT(D65,1),1,0) -> 0

Sheet ตรวจสอบเงื่อนไข
A1: ตรวจสอบเงื่อนไขอัตโนมัติ (ทุกค่าต้องเป็น 1 / ผลสรุปต้องเป็น ผ่าน)
A3: ตาราง 1: จำนวนครั้งที่แต่ละทีมเข้าแต่ละฐาน (ต้องเป็น 1 ทุกช่อง) | K3: ตาราง 2: จำนวนครั้งที่แต่ละทีมลงเล่นในแต่ละรอบ (ต้องเป็น 1 ทุกช่อง)
A4: ทีม | B4: ฐาน 1 | C4: ฐาน 2 | D4: ฐาน 3 | E4: ฐาน 4 | F4: ฐาน 5 | G4: ฐาน 6 | H4: ฐาน 7 | I4: ฐาน 8 | K4: ทีม | L4: รอบ 1 | M4: รอบ 2 | N4: รอบ 3 | O4: รอบ 4 | P4: รอบ 5 | Q4: รอบ 6 | R4: รอบ 7 | S4: รอบ 8
A5: 1A | B5: =COUNTIFS(ข้อมูลดิบ!$C$2:$C$65,$A5,ข้อมูลดิบ!$B$2:$B$65,1)+COUNTIFS(ข้อมูลดิบ!$D$2:$D$65,$A5,ข้อมูลดิบ!$B$2:$B$65,1) -> 1 | C5: =COUNTIFS(ข้อมูลดิบ!$C$2:$C$65,$A5,ข้อมูลดิบ!$B$2:$B$65,2)+COUNTIFS(ข้อมูลดิบ!$D$2:$D$65,$A5,ข้อมูลดิบ!$B$2:$B$65,2) -> 1 | D5: =COUNTIFS(ข้อมูลดิบ!$C$2:$C$65,$A5,ข้อมูลดิบ!$B$2:$B$65,3)+COUNTIFS(ข้อมูลดิบ!$D$2:$D$65,$A5,ข้อมูลดิบ!$B$2:$B$65,3) -> 1 | E5: =COUNTIFS(ข้อมูลดิบ!$C$2:$C$65,$A5,ข้อมูลดิบ!$B$2:$B$65,4)+COUNTIFS(ข้อมูลดิบ!$D$2:$D$65,$A5,ข้อมูลดิบ!$B$2:$B$65,4) -> 1 | F5: =COUNTIFS(ข้อมูลดิบ!$C$2:$C$65,$A5,ข้อมูลดิบ!$B$2:$B$65,5)+COUNTIFS(ข้อมูลดิบ!$D$2:$D$65,$A5,ข้อมูลดิบ!$B$2:$B$65,5) -> 1 | G5: =COUNTIFS(ข้อมูลดิบ!$C$2:$C$65,$A5,ข้อมูลดิบ!$B$2:$B$65,6)+COUNTIFS(ข้อมูลดิบ!$D$2:$D$65,$A5,ข้อมูลดิบ!$B$2:$B$65,6) -> 1 | H5: =COUNTIFS(ข้อมูลดิบ!$C$2:$C$65,$A5,ข้อมูลดิบ!$B$2:$B$65,7)+COUNTIFS(ข้อมูลดิบ!$D$2:$D$65,$A5,ข้อมูลดิบ!$B$2:$B$65,7) -> 1 | I5: =COUNTIFS(ข้อมูลดิบ!$C$2:$C$65,$A5,ข้อมูลดิบ!$B$2:$B$65,8)+COUNTIFS(ข้อมูลดิบ!$D$2:$D$65,$A5,ข้อมูลดิบ!$B$2:$B$65,8) -> 1 | K5: 1A | L5: =COUNTIFS(ข้อมูลดิบ!$C$2:$C$65,$K5,ข้อมูลดิบ!$A$2:$A$65,1)+COUNTIFS(ข้อมูลดิบ!$D$2:$D$65,$K5,ข้อมูลดิบ!$A$2:$A$65,1) -> 1 | M5: =COUNTIFS(ข้อมูลดิบ!$C$2:$C$65,$K5,ข้อมูลดิบ!$A$2:$A$65,2)+COUNTIFS(ข้อมูลดิบ!$D$2:$D$65,$K5,ข้อมูลดิบ!$A$2:$A$65,2) -> 1 | N5: =COUNTIFS(ข้อมูลดิบ!$C$2:$C$65,$K5,ข้อมูลดิบ!$A$2:$A$65,3)+COUNTIFS(ข้อมูลดิบ!$D$2:$D$65,$K5,ข้อมูลดิบ!$A$2:$A$65,3) -> 1 | O5: =COUNTIFS(ข้อมูลดิบ!$C$2:$C$65,$K5,ข้อมูลดิบ!$A$2:$A$65,4)+COUNTIFS(ข้อมูลดิบ!$D$2:$D$65,$K5,ข้อมูลดิบ!$A$2:$A$65,4) -> 1 | P5: =COUNTIFS(ข้อมูลดิบ!$C$2:$C$65,$K5,ข้อมูลดิบ!$A$2:$A$65,5)+COUNTIFS(ข้อมูลดิบ!$D$2:$D$65,$K5,ข้อมูลดิบ!$A$2:$A$65,5) -> 1 | Q5: =COUNTIFS(ข้อมูลดิบ!$C$2:$C$65,$K5,ข้อมูลดิบ!$A$2:$A$65,6)+COUNTIFS(ข้อมูลดิบ!$D$2:$D$65,$K5,ข้อมูลดิบ!$A$2:$A$65,6) -> 1 | R5: =COUNTIFS(ข้อมูลดิบ!$C$2:$C$65,$K5,ข้อมูลดิบ!$A$2:$A$65,7)+COUNTIFS(ข้อมูลดิบ!$D$2:$D$65,$K5,ข้อมูลดิบ!$A$2:$A$65,7) -> 1 | S5: =COUNTIFS(ข้อมูลดิบ!$C$2:$C$65,$K5,ข้อมูลดิบ!$A$2:$A$65,8)+COUNTIFS(ข้อมูลดิบ!$D$2:$D$65,$K5,ข้อมูลดิบ!$A$2:$A$65,8) -> 1
A6: 1B | B6: =COUNTIFS(ข้อมูลดิบ!$C$2:$C$65,$A6,ข้อมูลดิบ!$B$2:$B$65,1)+COUNTIFS(ข้อมูลดิบ!$D$2:$D$65,$A6,ข้อมูลดิบ!$B$2:$B$65,1) -> 1 | C6: =COUNTIFS(ข้อมูลดิบ!$C$2:$C$65,$A6,ข้อมูลดิบ!$B$2:$B$65,2)+COUNTIFS(ข้อมูลดิบ!$D$2:$D$65,$A6,ข้อมูลดิบ!$B$2:$B$65,2) -> 1 | D6: =COUNTIFS(ข้อมูลดิบ!$C$2:$C$65,$A6,ข้อมูลดิบ!$B$2:$B$65,3)+COUNTIFS(ข้อมูลดิบ!$D$2:$D$65,$A6,ข้อมูลดิบ!$B$2:$B$65,3) -> 1 | E6: =COUNTIFS(ข้อมูลดิบ!$C$2:$C$65,$A6,ข้อมูลดิบ!$B$2:$B$65,4)+COUNTIFS(ข้อมูลดิบ!$D$2:$D$65,$A6,ข้อมูลดิบ!$B$2:$B$65,4) -> 1 | F6: =COUNTIFS(ข้อมูลดิบ!$C$2:$C$65,$A6,ข้อมูลดิบ!$B$2:$B$65,5)+COUNTIFS(ข้อมูลดิบ!$D$2:$D$65,$A6,ข้อมูลดิบ!$B$2:$B$65,5) -> 1 | G6: =COUNTIFS(ข้อมูลดิบ!$C$2:$C$65,$A6,ข้อมูลดิบ!$B$2:$B$65,6)+COUNTIFS(ข้อมูลดิบ!$D$2:$D$65,$A6,ข้อมูลดิบ!$B$2:$B$65,6) -> 1 | H6: =COUNTIFS(ข้อมูลดิบ!$C$2:$C$65,$A6,ข้อมูลดิบ!$B$2:$B$65,7)+COUNTIFS(ข้อมูลดิบ!$D$2:$D$65,$A6,ข้อมูลดิบ!$B$2:$B$65,7) -> 1 | I6: =COUNTIFS(ข้อมูลดิบ!$C$2:$C$65,$A6,ข้อมูลดิบ!$B$2:$B$65,8)+COUNTIFS(ข้อมูลดิบ!$D$2:$D$65,$A6,ข้อมูลดิบ!$B$2:$B$65,8) -> 1 | K6: 1B | L6: =COUNTIFS(ข้อมูลดิบ!$C$2:$C$65,$K6,ข้อมูลดิบ!$A$2:$A$65,1)+COUNTIFS(ข้อมูลดิบ!$D$2:$D$65,$K6,ข้อมูลดิบ!$A$2:$A$65,1) -> 1 | M6: =COUNTIFS(ข้อมูลดิบ!$C$2:$C$65,$K6,ข้อมูลดิบ!$A$2:$A$65,2)+COUNTIFS(ข้อมูลดิบ!$D$2:$D$65,$K6,ข้อมูลดิบ!$A$2:$A$65,2) -> 1 | N6: =COUNTIFS(ข้อมูลดิบ!$C$2:$C$65,$K6,ข้อมูลดิบ!$A$2:$A$65,3)+COUNTIFS(ข้อมูลดิบ!$D$2:$D$65,$K6,ข้อมูลดิบ!$A$2:$A$65,3) -> 1 | O6: =COUNTIFS(ข้อมูลดิบ!$C$2:$C$65,$K6,ข้อมูลดิบ!$A$2:$A$65,4)+COUNTIFS(ข้อมูลดิบ!$D$2:$D$65,$K6,ข้อมูลดิบ!$A$2:$A$65,4) -> 1 | P6: =COUNTIFS(ข้อมูลดิบ!$C$2:$C$65,$K6,ข้อมูลดิบ!$A$2:$A$65,5)+COUNTIFS(ข้อมูลดิบ!$D$2:$D$65,$K6,ข้อมูลดิบ!$A$2:$A$65,5) -> 1 | Q6: =COUNTIFS(ข้อมูลดิบ!$C$2:$C$65,$K6,ข้อมูลดิบ!$A$2:$A$65,6)+COUNTIFS(ข้อมูลดิบ!$D$2:$D$65,$K6,ข้อมูลดิบ!$A$2:$A$65,6) -> 1 | R6: =COUNTIFS(ข้อมูลดิบ!$C$2:$C$65,$K6,ข้อมูลดิบ!$A$2:$A$65,7)+COUNTIFS(ข้อมูลดิบ!$D$2:$D$65,$K6,ข้อมูลดิบ!$A$2:$A$65,7) -> 1 | S6: =COUNTIFS(ข้อมูลดิบ!$C$2:$C$65,$K6,ข้อมูลดิบ!$A$2:$A$65,8)+COUNTIFS(ข้อมูลดิบ!$D$2:$D$65,$K6,ข้อมูลดิบ!$A$2:$A$65,8) -> 1
A7: 2A | B7: =COUNTIFS(ข้อมูลดิบ!$C$2:$C$65,$A7,ข้อมูลดิบ!$B$2:$B$65,1)+COUNTIFS(ข้อมูลดิบ!$D$2:$D$65,$A7,ข้อมูลดิบ!$B$2:$B$65,1) -> 1 | C7: =COUNTIFS(ข้อมูลดิบ!$C$2:$C$65,$A7,ข้อมูลดิบ!$B$2:$B$65,2)+COUNTIFS(ข้อมูลดิบ!$D$2:$D$65,$A7,ข้อมูลดิบ!$B$2:$B$65,2) -> 1 | D7: =COUNTIFS(ข้อมูลดิบ!$C$2:$C$65,$A7,ข้อมูลดิบ!$B$2:$B$65,3)+COUNTIFS(ข้อมูลดิบ!$D$2:$D$65,$A7,ข้อมูลดิบ!$B$2:$B$65,3) -> 1 | E7: =COUNTIFS(ข้อมูลดิบ!$C$2:$C$65,$A7,ข้อมูลดิบ!$B$2:$B$65,4)+COUNTIFS(ข้อมูลดิบ!$D$2:$D$65,$A7,ข้อมูลดิบ!$B$2:$B$65,4) -> 1 | F7: =COUNTIFS(ข้อมูลดิบ!$C$2:$C$65,$A7,ข้อมูลดิบ!$B$2:$B$65,5)+COUNTIFS(ข้อมูลดิบ!$D$2:$D$65,$A7,ข้อมูลดิบ!$B$2:$B$65,5) -> 1 | G7: =COUNTIFS(ข้อมูลดิบ!$C$2:$C$65,$A7,ข้อมูลดิบ!$B$2:$B$65,6)+COUNTIFS(ข้อมูลดิบ!$D$2:$D$65,$A7,ข้อมูลดิบ!$B$2:$B$65,6) -> 1 | H7: =COUNTIFS(ข้อมูลดิบ!$C$2:$C$65,$A7,ข้อมูลดิบ!$B$2:$B$65,7)+COUNTIFS(ข้อมูลดิบ!$D$2:$D$65,$A7,ข้อมูลดิบ!$B$2:$B$65,7) -> 1 | I7: =COUNTIFS(ข้อมูลดิบ!$C$2:$C$65,$A7,ข้อมูลดิบ!$B$2:$B$65,8)+COUNTIFS(ข้อมูลดิบ!$D$2:$D$65,$A7,ข้อมูลดิบ!$B$2:$B$65,8) -> 1 | K7: 2A | L7: =COUNTIFS(ข้อมูลดิบ!$C$2:$C$65,$K7,ข้อมูลดิบ!$A$2:$A$65,1)+COUNTIFS(ข้อมูลดิบ!$D$2:$D$65,$K7,ข้อมูลดิบ!$A$2:$A$65,1) -> 1 | M7: =COUNTIFS(ข้อมูลดิบ!$C$2:$C$65,$K7,ข้อมูลดิบ!$A$2:$A$65,2)+COUNTIFS(ข้อมูลดิบ!$D$2:$D$65,$K7,ข้อมูลดิบ!$A$2:$A$65,2) -> 1 | N7: =COUNTIFS(ข้อมูลดิบ!$C$2:$C$65,$K7,ข้อมูลดิบ!$A$2:$A$65,3)+COUNTIFS(ข้อมูลดิบ!$D$2:$D$65,$K7,ข้อมูลดิบ!$A$2:$A$65,3) -> 1 | O7: =COUNTIFS(ข้อมูลดิบ!$C$2:$C$65,$K7,ข้อมูลดิบ!$A$2:$A$65,4)+COUNTIFS(ข้อมูลดิบ!$D$2:$D$65,$K7,ข้อมูลดิบ!$A$2:$A$65,4) -> 1 | P7: =COUNTIFS(ข้อมูลดิบ!$C$2:$C$65,$K7,ข้อมูลดิบ!$A$2:$A$65,5)+COUNTIFS(ข้อมูลดิบ!$D$2:$D$65,$K7,ข้อมูลดิบ!$A$2:$A$65,5) -> 1 | Q7: =COUNTIFS(ข้อมูลดิบ!$C$2:$C$65,$K7,ข้อมูลดิบ!$A$2:$A$65,6)+COUNTIFS(ข้อมูลดิบ!$D$2:$D$65,$K7,ข้อมูลดิบ!$A$2:$A$65,6) -> 1 | R7: =COUNTIFS(ข้อมูลดิบ!$C$2:$C$65,$K7,ข้อมูลดิบ!$A$2:$A$65,7)+COUNTIFS(ข้อมูลดิบ!$D$2:$D$65,$K7,ข้อมูลดิบ!$A$2:$A$65,7) -> 1 | S7: =COUNTIFS(ข้อมูลดิบ!$C$2:$C$65,$K7,ข้อมูลดิบ!$A$2:$A$65,8)+COUNTIFS(ข้อมูลดิบ!$D$2:$D$65,$K7,ข้อมูลดิบ!$A$2:$A$65,8) -> 1
A8: 2B | B8: =COUNTIFS(ข้อมูลดิบ!$C$2:$C$65,$A8,ข้อมูลดิบ!$B$2:$B$65,1)+COUNTIFS(ข้อมูลดิบ!$D$2:$D$65,$A8,ข้อมูลดิบ!$B$2:$B$65,1) -> 1 | C8: =COUNTIFS(ข้อมูลดิบ!$C$2:$C$65,$A8,ข้อมูลดิบ!$B$2:$B$65,2)+COUNTIFS(ข้อมูลดิบ!$D$2:$D$65,$A8,ข้อมูลดิบ!$B$2:$B$65,2) -> 1 | D8: =COUNTIFS(ข้อมูลดิบ!$C$2:$C$65,$A8,ข้อมูลดิบ!$B$2:$B$65,3)+COUNTIFS(ข้อมูลดิบ!$D$2:$D$65,$A8,ข้อมูลดิบ!$B$2:$B$65,3) -> 1 | E8: =COUNTIFS(ข้อมูลดิบ!$C$2:$C$65,$A8,ข้อมูลดิบ!$B$2:$B$65,4)+COUNTIFS(ข้อมูลดิบ!$D$2:$D$65,$A8,ข้อมูลดิบ!$B$2:$B$65,4) -> 1 | F8: =COUNTIFS(ข้อมูลดิบ!$C$2:$C$65,$A8,ข้อมูลดิบ!$B$2:$B$65,5)+COUNTIFS(ข้อมูลดิบ!$D$2:$D$65,$A8,ข้อมูลดิบ!$B$2:$B$65,5) -> 1 | G8: =COUNTIFS(ข้อมูลดิบ!$C$2:$C$65,$A8,ข้อมูลดิบ!$B$2:$B$65,6)+COUNTIFS(ข้อมูลดิบ!$D$2:$D$65,$A8,ข้อมูลดิบ!$B$2:$B$65,6) -> 1 | H8: =COUNTIFS(ข้อมูลดิบ!$C$2:$C$65,$A8,ข้อมูลดิบ!$B$2:$B$65,7)+COUNTIFS(ข้อมูลดิบ!$D$2:$D$65,$A8,ข้อมูลดิบ!$B$2:$B$65,7) -> 1 | I8: =COUNTIFS(ข้อมูลดิบ!$C$2:$C$65,$A8,ข้อมูลดิบ!$B$2:$B$65,8)+COUNTIFS(ข้อมูลดิบ!$D$2:$D$65,$A8,ข้อมูลดิบ!$B$2:$B$65,8) -> 1 | K8: 2B | L8: =COUNTIFS(ข้อมูลดิบ!$C$2:$C$65,$K8,ข้อมูลดิบ!$A$2:$A$65,1)+COUNTIFS(ข้อมูลดิบ!$D$2:$D$65,$K8,ข้อมูลดิบ!$A$2:$A$65,1) -> 1 | M8: =COUNTIFS(ข้อมูลดิบ!$C$2:$C$65,$K8,ข้อมูลดิบ!$A$2:$A$65,2)+COUNTIFS(ข้อมูลดิบ!$D$2:$D$65,$K8,ข้อมูลดิบ!$A$2:$A$65,2) -> 1 | N8: =COUNTIFS(ข้อมูลดิบ!$C$2:$C$65,$K8,ข้อมูลดิบ!$A$2:$A$65,3)+COUNTIFS(ข้อมูลดิบ!$D$2:$D$65,$K8,ข้อมูลดิบ!$A$2:$A$65,3) -> 1 | O8: =COUNTIFS(ข้อมูลดิบ!$C$2:$C$65,$K8,ข้อมูลดิบ!$A$2:$A$65,4)+COUNTIFS(ข้อมูลดิบ!$D$2:$D$65,$K8,ข้อมูลดิบ!$A$2:$A$65,4) -> 1 | P8: =COUNTIFS(ข้อมูลดิบ!$C$2:$C$65,$K8,ข้อมูลดิบ!$A$2:$A$65,5)+COUNTIFS(ข้อมูลดิบ!$D$2:$D$65,$K8,ข้อมูลดิบ!$A$2:$A$65,5) -> 1 | Q8: =COUNTIFS(ข้อมูลดิบ!$C$2:$C$65,$K8,ข้อมูลดิบ!$A$2:$A$65,6)+COUNTIFS(ข้อมูลดิบ!$D$2:$D$65,$K8,ข้อมูลดิบ!$A$2:$A$65,6) -> 1 | R8: =COUNTIFS(ข้อมูลดิบ!$C$2:$C$65,$K8,ข้อมูลดิบ!$A$2:$A$65,7)+COUNTIFS(ข้อมูลดิบ!$D$2:$D$65,$K8,ข้อมูลดิบ!$A$2:$A$65,7) -> 1 | S8: =COUNTIFS(ข้อมูลดิบ!$C$2:$C$65,$K8,ข้อมูลดิบ!$A$2:$A$65,8)+COUNTIFS(ข้อมูลดิบ!$D$2:$D$65,$K8,ข้อมูลดิบ!$A$2:$A$65,8) -> 1
A9: 3A | B9: =COUNTIFS(ข้อมูลดิบ!$C$2:$C$65,$A9,ข้อมูลดิบ!$B$2:$B$65,1)+COUNTIFS(ข้อมูลดิบ!$D$2:$D$65,$A9,ข้อมูลดิบ!$B$2:$B$65,1) -> 1 | C9: =COUNTIFS(ข้อมูลดิบ!$C$2:$C$65,$A9,ข้อมูลดิบ!$B$2:$B$65,2)+COUNTIFS(ข้อมูลดิบ!$D$2:$D$65,$A9,ข้อมูลดิบ!$B$2:$B$65,2) -> 1 | D9: =COUNTIFS(ข้อมูลดิบ!$C$2:$C$65,$A9,ข้อมูลดิบ!$B$2:$B$65,3)+COUNTIFS(ข้อมูลดิบ!$D$2:$D$65,$A9,ข้อมูลดิบ!$B$2:$B$65,3) -> 1 | E9: =COUNTIFS(ข้อมูลดิบ!$C$2:$C$65,$A9,ข้อมูลดิบ!$B$2:$B$65,4)+COUNTIFS(ข้อมูลดิบ!$D$2:$D$65,$A9,ข้อมูลดิบ!$B$2:$B$65,4) -> 1 | F9: =COUNTIFS(ข้อมูลดิบ!$C$2:$C$65,$A9,ข้อมูลดิบ!$B$2:$B$65,5)+COUNTIFS(ข้อมูลดิบ!$D$2:$D$65,$A9,ข้อมูลดิบ!$B$2:$B$65,5) -> 1 | G9: =COUNTIFS(ข้อมูลดิบ!$C$2:$C$65,$A9,ข้อมูลดิบ!$B$2:$B$65,6)+COUNTIFS(ข้อมูลดิบ!$D$2:$D$65,$A9,ข้อมูลดิบ!$B$2:$B$65,6) -> 1 | H9: =COUNTIFS(ข้อมูลดิบ!$C$2:$C$65,$A9,ข้อมูลดิบ!$B$2:$B$65,7)+COUNTIFS(ข้อมูลดิบ!$D$2:$D$65,$A9,ข้อมูลดิบ!$B$2:$B$65,7) -> 1 | I9: =COUNTIFS(ข้อมูลดิบ!$C$2:$C$65,$A9,ข้อมูลดิบ!$B$2:$B$65,8)+COUNTIFS(ข้อมูลดิบ!$D$2:$D$65,$A9,ข้อมูลดิบ!$B$2:$B$65,8) -> 1 | K9: 3A | L9: =COUNTIFS(ข้อมูลดิบ!$C$2:$C$65,$K9,ข้อมูลดิบ!$A$2:$A$65,1)+COUNTIFS(ข้อมูลดิบ!$D$2:$D$65,$K9,ข้อมูลดิบ!$A$2:$A$65,1) -> 1 | M9: =COUNTIFS(ข้อมูลดิบ!$C$2:$C$65,$K9,ข้อมูลดิบ!$A$2:$A$65,2)+COUNTIFS(ข้อมูลดิบ!$D$2:$D$65,$K9,ข้อมูลดิบ!$A$2:$A$65,2) -> 1 | N9: =COUNTIFS(ข้อมูลดิบ!$C$2:$C$65,$K9,ข้อมูลดิบ!$A$2:$A$65,3)+COUNTIFS(ข้อมูลดิบ!$D$2:$D$65,$K9,ข้อมูลดิบ!$A$2:$A$65,3) -> 1 | O9: =COUNTIFS(ข้อมูลดิบ!$C$2:$C$65,$K9,ข้อมูลดิบ!$A$2:$A$65,4)+COUNTIFS(ข้อมูลดิบ!$D$2:$D$65,$K9,ข้อมูลดิบ!$A$2:$A$65,4) -> 1 | P9: =COUNTIFS(ข้อมูลดิบ!$C$2:$C$65,$K9,ข้อมูลดิบ!$A$2:$A$65,5)+COUNTIFS(ข้อมูลดิบ!$D$2:$D$65,$K9,ข้อมูลดิบ!$A$2:$A$65,5) -> 1 | Q9: =COUNTIFS(ข้อมูลดิบ!$C$2:$C$65,$K9,ข้อมูลดิบ!$A$2:$A$65,6)+COUNTIFS(ข้อมูลดิบ!$D$2:$D$65,$K9,ข้อมูลดิบ!$A$2:$A$65,6) -> 1 | R9: =COUNTIFS(ข้อมูลดิบ!$C$2:$C$65,$K9,ข้อมูลดิบ!$A$2:$A$65,7)+COUNTIFS(ข้อมูลดิบ!$D$2:$D$65,$K9,ข้อมูลดิบ!$A$2:$A$65,7) -> 1 | S9: =COUNTIFS(ข้อมูลดิบ!$C$2:$C$65,$K9,ข้อมูลดิบ!$A$2:$A$65,8)+COUNTIFS(ข้อมูลดิบ!$D$2:$D$65,$K9,ข้อมูลดิบ!$A$2:$A$65,8) -> 1
A10: 3B | B10: =COUNTIFS(ข้อมูลดิบ!$C$2:$C$65,$A10,ข้อมูลดิบ!$B$2:$B$65,1)+COUNTIFS(ข้อมูลดิบ!$D$2:$D$65,$A10,ข้อมูลดิบ!$B$2:$B$65,1) -> 1 | C10: =COUNTIFS(ข้อมูลดิบ!$C$2:$C$65,$A10,ข้อมูลดิบ!$B$2:$B$65,2)+COUNTIFS(ข้อมูลดิบ!$D$2:$D$65,$A10,ข้อมูลดิบ!$B$2:$B$65,2) -> 1 | D10: =COUNTIFS(ข้อมูลดิบ!$C$2:$C$65,$A10,ข้อมูลดิบ!$B$2:$B$65,3)+COUNTIFS(ข้อมูลดิบ!$D$2:$D$65,$A10,ข้อมูลดิบ!$B$2:$B$65,3) -> 1 | E10: =COUNTIFS(ข้อมูลดิบ!$C$2:$C$65,$A10,ข้อมูลดิบ!$B$2:$B$65,4)+COUNTIFS(ข้อมูลดิบ!$D$2:$D$65,$A10,ข้อมูลดิบ!$B$2:$B$65,4) -> 1 | F10: =COUNTIFS(ข้อมูลดิบ!$C$2:$C$65,$A10,ข้อมูลดิบ!$B$2:$B$65,5)+COUNTIFS(ข้อมูลดิบ!$D$2:$D$65,$A10,ข้อมูลดิบ!$B$2:$B$65,5) -> 1 | G10: =COUNTIFS(ข้อมูลดิบ!$C$2:$C$65,$A10,ข้อมูลดิบ!$B$2:$B$65,6)+COUNTIFS(ข้อมูลดิบ!$D$2:$D$65,$A10,ข้อมูลดิบ!$B$2:$B$65,6) -> 1 | H10: =COUNTIFS(ข้อมูลดิบ!$C$2:$C$65,$A10,ข้อมูลดิบ!$B$2:$B$65,7)+COUNTIFS(ข้อมูลดิบ!$D$2:$D$65,$A10,ข้อมูลดิบ!$B$2:$B$65,7) -> 1 | I10: =COUNTIFS(ข้อมูลดิบ!$C$2:$C$65,$A10,ข้อมูลดิบ!$B$2:$B$65,8)+COUNTIFS(ข้อมูลดิบ!$D$2:$D$65,$A10,ข้อมูลดิบ!$B$2:$B$65,8) -> 1 | K10: 3B | L10: =COUNTIFS(ข้อมูลดิบ!$C$2:$C$65,$K10,ข้อมูลดิบ!$A$2:$A$65,1)+COUNTIFS(ข้อมูลดิบ!$D$2:$D$65,$K10,ข้อมูลดิบ!$A$2:$A$65,1) -> 1 | M10: =COUNTIFS(ข้อมูลดิบ!$C$2:$C$65,$K10,ข้อมูลดิบ!$A$2:$A$65,2)+COUNTIFS(ข้อมูลดิบ!$D$2:$D$65,$K10,ข้อมูลดิบ!$A$2:$A$65,2) -> 1 | N10: =COUNTIFS(ข้อมูลดิบ!$C$2:$C$65,$K10,ข้อมูลดิบ!$A$2:$A$65,3)+COUNTIFS(ข้อมูลดิบ!$D$2:$D$65,$K10,ข้อมูลดิบ!$A$2:$A$65,3) -> 1 | O10: =COUNTIFS(ข้อมูลดิบ!$C$2:$C$65,$K10,ข้อมูลดิบ!$A$2:$A$65,4)+COUNTIFS(ข้อมูลดิบ!$D$2:$D$65,$K10,ข้อมูลดิบ!$A$2:$A$65,4) -> 1 | P10: =COUNTIFS(ข้อมูลดิบ!$C$2:$C$65,$K10,ข้อมูลดิบ!$A$2:$A$65,5)+COUNTIFS(ข้อมูลดิบ!$D$2:$D$65,$K10,ข้อมูลดิบ!$A$2:$A$65,5) -> 1 | Q10: =COUNTIFS(ข้อมูลดิบ!$C$2:$C$65,$K10,ข้อมูลดิบ!$A$2:$A$65,6)+COUNTIFS(ข้อมูลดิบ!$D$2:$D$65,$K10,ข้อมูลดิบ!$A$2:$A$65,6) -> 1 | R10: =COUNTIFS(ข้อมูลดิบ!$C$2:$C$65,$K10,ข้อมูลดิบ!$A$2:$A$65,7)+COUNTIFS(ข้อมูลดิบ!$D$2:$D$65,$K10,ข้อมูลดิบ!$A$2:$A$65,7) -> 1 | S10: =COUNTIFS(ข้อมูลดิบ!$C$2:$C$65,$K10,ข้อมูลดิบ!$A$2:$A$65,8)+COUNTIFS(ข้อมูลดิบ!$D$2:$D$65,$K10,ข้อมูลดิบ!$A$2:$A$65,8) -> 1
A11: 4A | B11: =COUNTIFS(ข้อมูลดิบ!$C$2:$C$65,$A11,ข้อมูลดิบ!$B$2:$B$65,1)+COUNTIFS(ข้อมูลดิบ!$D$2:$D$65,$A11,ข้อมูลดิบ!$B$2:$B$65,1) -> 1 | C11: =COUNTIFS(ข้อมูลดิบ!$C$2:$C$65,$A11,ข้อมูลดิบ!$B$2:$B$65,2)+COUNTIFS(ข้อมูลดิบ!$D$2:$D$65,$A11,ข้อมูลดิบ!$B$2:$B$65,2) -> 1 | D11: =COUNTIFS(ข้อมูลดิบ!$C$2:$C$65,$A11,ข้อมูลดิบ!$B$2:$B$65,3)+COUNTIFS(ข้อมูลดิบ!$D$2:$D$65,$A11,ข้อมูลดิบ!$B$2:$B$65,3) -> 1 | E11: =COUNTIFS(ข้อมูลดิบ!$C$2:$C$65,$A11,ข้อมูลดิบ!$B$2:$B$65,4)+COUNTIFS(ข้อมูลดิบ!$D$2:$D$65,$A11,ข้อมูลดิบ!$B$2:$B$65,4) -> 1 | F11: =COUNTIFS(ข้อมูลดิบ!$C$2:$C$65,$A11,ข้อมูลดิบ!$B$2:$B$65,5)+COUNTIFS(ข้อมูลดิบ!$D$2:$D$65,$A11,ข้อมูลดิบ!$B$2:$B$65,5) -> 1 | G11: =COUNTIFS(ข้อมูลดิบ!$C$2:$C$65,$A11,ข้อมูลดิบ!$B$2:$B$65,6)+COUNTIFS(ข้อมูลดิบ!$D$2:$D$65,$A11,ข้อมูลดิบ!$B$2:$B$65,6) -> 1 | H11: =COUNTIFS(ข้อมูลดิบ!$C$2:$C$65,$A11,ข้อมูลดิบ!$B$2:$B$65,7)+COUNTIFS(ข้อมูลดิบ!$D$2:$D$65,$A11,ข้อมูลดิบ!$B$2:$B$65,7) -> 1 | I11: =COUNTIFS(ข้อมูลดิบ!$C$2:$C$65,$A11,ข้อมูลดิบ!$B$2:$B$65,8)+COUNTIFS(ข้อมูลดิบ!$D$2:$D$65,$A11,ข้อมูลดิบ!$B$2:$B$65,8) -> 1 | K11: 4A | L11: =COUNTIFS(ข้อมูลดิบ!$C$2:$C$65,$K11,ข้อมูลดิบ!$A$2:$A$65,1)+COUNTIFS(ข้อมูลดิบ!$D$2:$D$65,$K11,ข้อมูลดิบ!$A$2:$A$65,1) -> 1 | M11: =COUNTIFS(ข้อมูลดิบ!$C$2:$C$65,$K11,ข้อมูลดิบ!$A$2:$A$65,2)+COUNTIFS(ข้อมูลดิบ!$D$2:$D$65,$K11,ข้อมูลดิบ!$A$2:$A$65,2) -> 1 | N11: =COUNTIFS(ข้อมูลดิบ!$C$2:$C$65,$K11,ข้อมูลดิบ!$A$2:$A$65,3)+COUNTIFS(ข้อมูลดิบ!$D$2:$D$65,$K11,ข้อมูลดิบ!$A$2:$A$65,3) -> 1 | O11: =COUNTIFS(ข้อมูลดิบ!$C$2:$C$65,$K11,ข้อมูลดิบ!$A$2:$A$65,4)+COUNTIFS(ข้อมูลดิบ!$D$2:$D$65,$K11,ข้อมูลดิบ!$A$2:$A$65,4) -> 1 | P11: =COUNTIFS(ข้อมูลดิบ!$C$2:$C$65,$K11,ข้อมูลดิบ!$A$2:$A$65,5)+COUNTIFS(ข้อมูลดิบ!$D$2:$D$65,$K11,ข้อมูลดิบ!$A$2:$A$65,5) -> 1 | Q11: =COUNTIFS(ข้อมูลดิบ!$C$2:$C$65,$K11,ข้อมูลดิบ!$A$2:$A$65,6)+COUNTIFS(ข้อมูลดิบ!$D$2:$D$65,$K11,ข้อมูลดิบ!$A$2:$A$65,6) -> 1 | R11: =COUNTIFS(ข้อมูลดิบ!$C$2:$C$65,$K11,ข้อมูลดิบ!$A$2:$A$65,7)+COUNTIFS(ข้อมูลดิบ!$D$2:$D$65,$K11,ข้อมูลดิบ!$A$2:$A$65,7) -> 1 | S11: =COUNTIFS(ข้อมูลดิบ!$C$2:$C$65,$K11,ข้อมูลดิบ!$A$2:$A$65,8)+COUNTIFS(ข้อมูลดิบ!$D$2:$D$65,$K11,ข้อมูลดิบ!$A$2:$A$65,8) -> 1
A12: 4B | B12: =COUNTIFS(ข้อมูลดิบ!$C$2:$C$65,$A12,ข้อมูลดิบ!$B$2:$B$65,1)+COUNTIFS(ข้อมูลดิบ!$D$2:$D$65,$A12,ข้อมูลดิบ!$B$2:$B$65,1) -> 1 | C12: =COUNTIFS(ข้อมูลดิบ!$C$2:$C$65,$A12,ข้อมูลดิบ!$B$2:$B$65,2)+COUNTIFS(ข้อมูลดิบ!$D$2:$D$65,$A12,ข้อมูลดิบ!$B$2:$B$65,2) -> 1 | D12: =COUNTIFS(ข้อมูลดิบ!$C$2:$C$65,$A12,ข้อมูลดิบ!$B$2:$B$65,3)+COUNTIFS(ข้อมูลดิบ!$D$2:$D$65,$A12,ข้อมูลดิบ!$B$2:$B$65,3) -> 1 | E12: =COUNTIFS(ข้อมูลดิบ!$C$2:$C$65,$A12,ข้อมูลดิบ!$B$2:$B$65,4)+COUNTIFS(ข้อมูลดิบ!$D$2:$D$65,$A12,ข้อมูลดิบ!$B$2:$B$65,4) -> 1 | F12: =COUNTIFS(ข้อมูลดิบ!$C$2:$C$65,$A12,ข้อมูลดิบ!$B$2:$B$65,5)+COUNTIFS(ข้อมูลดิบ!$D$2:$D$65,$A12,ข้อมูลดิบ!$B$2:$B$65,5) -> 1 | G12: =COUNTIFS(ข้อมูลดิบ!$C$2:$C$65,$A12,ข้อมูลดิบ!$B$2:$B$65,6)+COUNTIFS(ข้อมูลดิบ!$D$2:$D$65,$A12,ข้อมูลดิบ!$B$2:$B$65,6) -> 1 | H12: =COUNTIFS(ข้อมูลดิบ!$C$2:$C$65,$A12,ข้อมูลดิบ!$B$2:$B$65,7)+COUNTIFS(ข้อมูลดิบ!$D$2:$D$65,$A12,ข้อมูลดิบ!$B$2:$B$65,7) -> 1 | I12: =COUNTIFS(ข้อมูลดิบ!$C$2:$C$65,$A12,ข้อมูลดิบ!$B$2:$B$65,8)+COUNTIFS(ข้อมูลดิบ!$D$2:$D$65,$A12,ข้อมูลดิบ!$B$2:$B$65,8) -> 1 | K12: 4B | L12: =COUNTIFS(ข้อมูลดิบ!$C$2:$C$65,$K12,ข้อมูลดิบ!$A$2:$A$65,1)+COUNTIFS(ข้อมูลดิบ!$D$2:$D$65,$K12,ข้อมูลดิบ!$A$2:$A$65,1) -> 1 | M12: =COUNTIFS(ข้อมูลดิบ!$C$2:$C$65,$K12,ข้อมูลดิบ!$A$2:$A$65,2)+COUNTIFS(ข้อมูลดิบ!$D$2:$D$65,$K12,ข้อมูลดิบ!$A$2:$A$65,2) -> 1 | N12: =COUNTIFS(ข้อมูลดิบ!$C$2:$C$65,$K12,ข้อมูลดิบ!$A$2:$A$65,3)+COUNTIFS(ข้อมูลดิบ!$D$2:$D$65,$K12,ข้อมูลดิบ!$A$2:$A$65,3) -> 1 | O12: =COUNTIFS(ข้อมูลดิบ!$C$2:$C$65,$K12,ข้อมูลดิบ!$A$2:$A$65,4)+COUNTIFS(ข้อมูลดิบ!$D$2:$D$65,$K12,ข้อมูลดิบ!$A$2:$A$65,4) -> 1 | P12: =COUNTIFS(ข้อมูลดิบ!$C$2:$C$65,$K12,ข้อมูลดิบ!$A$2:$A$65,5)+COUNTIFS(ข้อมูลดิบ!$D$2:$D$65,$K12,ข้อมูลดิบ!$A$2:$A$65,5) -> 1 | Q12: =COUNTIFS(ข้อมูลดิบ!$C$2:$C$65,$K12,ข้อมูลดิบ!$A$2:$A$65,6)+COUNTIFS(ข้อมูลดิบ!$D$2:$D$65,$K12,ข้อมูลดิบ!$A$2:$A$65,6) -> 1 | R12: =COUNTIFS(ข้อมูลดิบ!$C$2:$C$65,$K12,ข้อมูลดิบ!$A$2:$A$65,7)+COUNTIFS(ข้อมูลดิบ!$D$2:$D$65,$K12,ข้อมูลดิบ!$A$2:$A$65,7) -> 1 | S12: =COUNTIFS(ข้อมูลดิบ!$C$2:$C$65,$K12,ข้อมูลดิบ!$A$2:$A$65,8)+COUNTIFS(ข้อมูลดิบ!$D$2:$D$65,$K12,ข้อมูลดิบ!$A$2:$A$65,8) -> 1
A13: 5A | B13: =COUNTIFS(ข้อมูลดิบ!$C$2:$C$65,$A13,ข้อมูลดิบ!$B$2:$B$65,1)+COUNTIFS(ข้อมูลดิบ!$D$2:$D$65,$A13,ข้อมูลดิบ!$B$2:$B$65,1) -> 1 | C13: =COUNTIFS(ข้อมูลดิบ!$C$2:$C$65,$A13,ข้อมูลดิบ!$B$2:$B$65,2)+COUNTIFS(ข้อมูลดิบ!$D$2:$D$65,$A13,ข้อมูลดิบ!$B$2:$B$65,2) -> 1 | D13: =COUNTIFS(ข้อมูลดิบ!$C$2:$C$65,$A13,ข้อมูลดิบ!$B$2:$B$65,3)+COUNTIFS(ข้อมูลดิบ!$D$2:$D$65,$A13,ข้อมูลดิบ!$B$2:$B$65,3) -> 1 | E13: =COUNTIFS(ข้อมูลดิบ!$C$2:$C$65,$A13,ข้อมูลดิบ!$B$2:$B$65,4)+COUNTIFS(ข้อมูลดิบ!$D$2:$D$65,$A13,ข้อมูลดิบ!$B$2:$B$65,4) -> 1 | F13: =COUNTIFS(ข้อมูลดิบ!$C$2:$C$65,$A13,ข้อมูลดิบ!$B$2:$B$65,5)+COUNTIFS(ข้อมูลดิบ!$D$2:$D$65,$A13,ข้อมูลดิบ!$B$2:$B$65,5) -> 1 | G13: =COUNTIFS(ข้อมูลดิบ!$C$2:$C$65,$A13,ข้อมูลดิบ!$B$2:$B$65,6)+COUNTIFS(ข้อมูลดิบ!$D$2:$D$65,$A13,ข้อมูลดิบ!$B$2:$B$65,6) -> 1 | H13: =COUNTIFS(ข้อมูลดิบ!$C$2:$C$65,$A13,ข้อมูลดิบ!$B$2:$B$65,7)+COUNTIFS(ข้อมูลดิบ!$D$2:$D$65,$A13,ข้อมูลดิบ!$B$2:$B$65,7) -> 1 | I13: =COUNTIFS(ข้อมูลดิบ!$C$2:$C$65,$A13,ข้อมูลดิบ!$B$2:$B$65,8)+COUNTIFS(ข้อมูลดิบ!$D$2:$D$65,$A13,ข้อมูลดิบ!$B$2:$B$65,8) -> 1 | K13: 5A | L13: =COUNTIFS(ข้อมูลดิบ!$C$2:$C$65,$K13,ข้อมูลดิบ!$A$2:$A$65,1)+COUNTIFS(ข้อมูลดิบ!$D$2:$D$65,$K13,ข้อมูลดิบ!$A$2:$A$65,1) -> 1 | M13: =COUNTIFS(ข้อมูลดิบ!$C$2:$C$65,$K13,ข้อมูลดิบ!$A$2:$A$65,2)+COUNTIFS(ข้อมูลดิบ!$D$2:$D$65,$K13,ข้อมูลดิบ!$A$2:$A$65,2) -> 1 | N13: =COUNTIFS(ข้อมูลดิบ!$C$2:$C$65,$K13,ข้อมูลดิบ!$A$2:$A$65,3)+COUNTIFS(ข้อมูลดิบ!$D$2:$D$65,$K13,ข้อมูลดิบ!$A$2:$A$65,3) -> 1 | O13: =COUNTIFS(ข้อมูลดิบ!$C$2:$C$65,$K13,ข้อมูลดิบ!$A$2:$A$65,4)+COUNTIFS(ข้อมูลดิบ!$D$2:$D$65,$K13,ข้อมูลดิบ!$A$2:$A$65,4) -> 1 | P13: =COUNTIFS(ข้อมูลดิบ!$C$2:$C$65,$K13,ข้อมูลดิบ!$A$2:$A$65,5)+COUNTIFS(ข้อมูลดิบ!$D$2:$D$65,$K13,ข้อมูลดิบ!$A$2:$A$65,5) -> 1 | Q13: =COUNTIFS(ข้อมูลดิบ!$C$2:$C$65,$K13,ข้อมูลดิบ!$A$2:$A$65,6)+COUNTIFS(ข้อมูลดิบ!$D$2:$D$65,$K13,ข้อมูลดิบ!$A$2:$A$65,6) -> 1 | R13: =COUNTIFS(ข้อมูลดิบ!$C$2:$C$65,$K13,ข้อมูลดิบ!$A$2:$A$65,7)+COUNTIFS(ข้อมูลดิบ!$D$2:$D$65,$K13,ข้อมูลดิบ!$A$2:$A$65,7) -> 1 | S13: =COUNTIFS(ข้อมูลดิบ!$C$2:$C$65,$K13,ข้อมูลดิบ!$A$2:$A$65,8)+COUNTIFS(ข้อมูลดิบ!$D$2:$D$65,$K13,ข้อมูลดิบ!$A$2:$A$65,8) -> 1
A14: 5B | B14: =COUNTIFS(ข้อมูลดิบ!$C$2:$C$65,$A14,ข้อมูลดิบ!$B$2:$B$65,1)+COUNTIFS(ข้อมูลดิบ!$D$2:$D$65,$A14,ข้อมูลดิบ!$B$2:$B$65,1) -> 1 | C14: =COUNTIFS(ข้อมูลดิบ!$C$2:$C$65,$A14,ข้อมูลดิบ!$B$2:$B$65,2)+COUNTIFS(ข้อมูลดิบ!$D$2:$D$65,$A14,ข้อมูลดิบ!$B$2:$B$65,2) -> 1 | D14: =COUNTIFS(ข้อมูลดิบ!$C$2:$C$65,$A14,ข้อมูลดิบ!$B$2:$B$65,3)+COUNTIFS(ข้อมูลดิบ!$D$2:$D$65,$A14,ข้อมูลดิบ!$B$2:$B$65,3) -> 1 | E14: =COUNTIFS(ข้อมูลดิบ!$C$2:$C$65,$A14,ข้อมูลดิบ!$B$2:$B$65,4)+COUNTIFS(ข้อมูลดิบ!$D$2:$D$65,$A14,ข้อมูลดิบ!$B$2:$B$65,4) -> 1 | F14: =COUNTIFS(ข้อมูลดิบ!$C$2:$C$65,$A14,ข้อมูลดิบ!$B$2:$B$65,5)+COUNTIFS(ข้อมูลดิบ!$D$2:$D$65,$A14,ข้อมูลดิบ!$B$2:$B$65,5) -> 1 | G14: =COUNTIFS(ข้อมูลดิบ!$C$2:$C$65,$A14,ข้อมูลดิบ!$B$2:$B$65,6)+COUNTIFS(ข้อมูลดิบ!$D$2:$D$65,$A14,ข้อมูลดิบ!$B$2:$B$65,6) -> 1 | H14: =COUNTIFS(ข้อมูลดิบ!$C$2:$C$65,$A14,ข้อมูลดิบ!$B$2:$B$65,7)+COUNTIFS(ข้อมูลดิบ!$D$2:$D$65,$A14,ข้อมูลดิบ!$B$2:$B$65,7) -> 1 | I14: =COUNTIFS(ข้อมูลดิบ!$C$2:$C$65,$A14,ข้อมูลดิบ!$B$2:$B$65,8)+COUNTIFS(ข้อมูลดิบ!$D$2:$D$65,$A14,ข้อมูลดิบ!$B$2:$B$65,8) -> 1 | K14: 5B | L14: =COUNTIFS(ข้อมูลดิบ!$C$2:$C$65,$K14,ข้อมูลดิบ!$A$2:$A$65,1)+COUNTIFS(ข้อมูลดิบ!$D$2:$D$65,$K14,ข้อมูลดิบ!$A$2:$A$65,1) -> 1 | M14: =COUNTIFS(ข้อมูลดิบ!$C$2:$C$65,$K14,ข้อมูลดิบ!$A$2:$A$65,2)+COUNTIFS(ข้อมูลดิบ!$D$2:$D$65,$K14,ข้อมูลดิบ!$A$2:$A$65,2) -> 1 | N14: =COUNTIFS(ข้อมูลดิบ!$C$2:$C$65,$K14,ข้อมูลดิบ!$A$2:$A$65,3)+COUNTIFS(ข้อมูลดิบ!$D$2:$D$65,$K14,ข้อมูลดิบ!$A$2:$A$65,3) -> 1 | O14: =COUNTIFS(ข้อมูลดิบ!$C$2:$C$65,$K14,ข้อมูลดิบ!$A$2:$A$65,4)+COUNTIFS(ข้อมูลดิบ!$D$2:$D$65,$K14,ข้อมูลดิบ!$A$2:$A$65,4) -> 1 | P14: =COUNTIFS(ข้อมูลดิบ!$C$2:$C$65,$K14,ข้อมูลดิบ!$A$2:$A$65,5)+COUNTIFS(ข้อมูลดิบ!$D$2:$D$65,$K14,ข้อมูลดิบ!$A$2:$A$65,5) -> 1 | Q14: =COUNTIFS(ข้อมูลดิบ!$C$2:$C$65,$K14,ข้อมูลดิบ!$A$2:$A$65,6)+COUNTIFS(ข้อมูลดิบ!$D$2:$D$65,$K14,ข้อมูลดิบ!$A$2:$A$65,6) -> 1 | R14: =COUNTIFS(ข้อมูลดิบ!$C$2:$C$65,$K14,ข้อมูลดิบ!$A$2:$A$65,7)+COUNTIFS(ข้อมูลดิบ!$D$2:$D$65,$K14,ข้อมูลดิบ!$A$2:$A$65,7) -> 1 | S14: =COUNTIFS(ข้อมูลดิบ!$C$2:$C$65,$K14,ข้อมูลดิบ!$A$2:$A$65,8)+COUNTIFS(ข้อมูลดิบ!$D$2:$D$65,$K14,ข้อมูลดิบ!$A$2:$A$65,8) -> 1
A15: 6A | B15: =COUNTIFS(ข้อมูลดิบ!$C$2:$C$65,$A15,ข้อมูลดิบ!$B$2:$B$65,1)+COUNTIFS(ข้อมูลดิบ!$D$2:$D$65,$A15,ข้อมูลดิบ!$B$2:$B$65,1) -> 1 | C15: =COUNTIFS(ข้อมูลดิบ!$C$2:$C$65,$A15,ข้อมูลดิบ!$B$2:$B$65,2)+COUNTIFS(ข้อมูลดิบ!$D$2:$D$65,$A15,ข้อมูลดิบ!$B$2:$B$65,2) -> 1 | D15: =COUNTIFS(ข้อมูลดิบ!$C$2:$C$65,$A15,ข้อมูลดิบ!$B$2:$B$65,3)+COUNTIFS(ข้อมูลดิบ!$D$2:$D$65,$A15,ข้อมูลดิบ!$B$2:$B$65,3) -> 1 | E15: =COUNTIFS(ข้อมูลดิบ!$C$2:$C$65,$A15,ข้อมูลดิบ!$B$2:$B$65,4)+COUNTIFS(ข้อมูลดิบ!$D$2:$D$65,$A15,ข้อมูลดิบ!$B$2:$B$65,4) -> 1 | F15: =COUNTIFS(ข้อมูลดิบ!$C$2:$C$65,$A15,ข้อมูลดิบ!$B$2:$B$65,5)+COUNTIFS(ข้อมูลดิบ!$D$2:$D$65,$A15,ข้อมูลดิบ!$B$2:$B$65,5) -> 1 | G15: =COUNTIFS(ข้อมูลดิบ!$C$2:$C$65,$A15,ข้อมูลดิบ!$B$2:$B$65,6)+COUNTIFS(ข้อมูลดิบ!$D$2:$D$65,$A15,ข้อมูลดิบ!$B$2:$B$65,6) -> 1 | H15: =COUNTIFS(ข้อมูลดิบ!$C$2:$C$65,$A15,ข้อมูลดิบ!$B$2:$B$65,7)+COUNTIFS(ข้อมูลดิบ!$D$2:$D$65,$A15,ข้อมูลดิบ!$B$2:$B$65,7) -> 1 | I15: =COUNTIFS(ข้อมูลดิบ!$C$2:$C$65,$A15,ข้อมูลดิบ!$B$2:$B$65,8)+COUNTIFS(ข้อมูลดิบ!$D$2:$D$65,$A15,ข้อมูลดิบ!$B$2:$B$65,8) -> 1 | K15: 6A | L15: =COUNTIFS(ข้อมูลดิบ!$C$2:$C$65,$K15,ข้อมูลดิบ!$A$2:$A$65,1)+COUNTIFS(ข้อมูลดิบ!$D$2:$D$65,$K15,ข้อมูลดิบ!$A$2:$A$65,1) -> 1 | M15: =COUNTIFS(ข้อมูลดิบ!$C$2:$C$65,$K15,ข้อมูลดิบ!$A$2:$A$65,2)+COUNTIFS(ข้อมูลดิบ!$D$2:$D$65,$K15,ข้อมูลดิบ!$A$2:$A$65,2) -> 1 | N15: =COUNTIFS(ข้อมูลดิบ!$C$2:$C$65,$K15,ข้อมูลดิบ!$A$2:$A$65,3)+COUNTIFS(ข้อมูลดิบ!$D$2:$D$65,$K15,ข้อมูลดิบ!$A$2:$A$65,3) -> 1 | O15: =COUNTIFS(ข้อมูลดิบ!$C$2:$C$65,$K15,ข้อมูลดิบ!$A$2:$A$65,4)+COUNTIFS(ข้อมูลดิบ!$D$2:$D$65,$K15,ข้อมูลดิบ!$A$2:$A$65,4) -> 1 | P15: =COUNTIFS(ข้อมูลดิบ!$C$2:$C$65,$K15,ข้อมูลดิบ!$A$2:$A$65,5)+COUNTIFS(ข้อมูลดิบ!$D$2:$D$65,$K15,ข้อมูลดิบ!$A$2:$A$65,5) -> 1 | Q15: =COUNTIFS(ข้อมูลดิบ!$C$2:$C$65,$K15,ข้อมูลดิบ!$A$2:$A$65,6)+COUNTIFS(ข้อมูลดิบ!$D$2:$D$65,$K15,ข้อมูลดิบ!$A$2:$A$65,6) -> 1 | R15: =COUNTIFS(ข้อมูลดิบ!$C$2:$C$65,$K15,ข้อมูลดิบ!$A$2:$A$65,7)+COUNTIFS(ข้อมูลดิบ!$D$2:$D$65,$K15,ข้อมูลดิบ!$A$2:$A$65,7) -> 1 | S15: =COUNTIFS(ข้อมูลดิบ!$C$2:$C$65,$K15,ข้อมูลดิบ!$A$2:$A$65,8)+COUNTIFS(ข้อมูลดิบ!$D$2:$D$65,$K15,ข้อมูลดิบ!$A$2:$A$65,8) -> 1
A16: 6B | B16: =COUNTIFS(ข้อมูลดิบ!$C$2:$C$65,$A16,ข้อมูลดิบ!$B$2:$B$65,1)+COUNTIFS(ข้อมูลดิบ!$D$2:$D$65,$A16,ข้อมูลดิบ!$B$2:$B$65,1) -> 1 | C16: =COUNTIFS(ข้อมูลดิบ!$C$2:$C$65,$A16,ข้อมูลดิบ!$B$2:$B$65,2)+COUNTIFS(ข้อมูลดิบ!$D$2:$D$65,$A16,ข้อมูลดิบ!$B$2:$B$65,2) -> 1 | D16: =COUNTIFS(ข้อมูลดิบ!$C$2:$C$65,$A16,ข้อมูลดิบ!$B$2:$B$65,3)+COUNTIFS(ข้อมูลดิบ!$D$2:$D$65,$A16,ข้อมูลดิบ!$B$2:$B$65,3) -> 1 | E16: =COUNTIFS(ข้อมูลดิบ!$C$2:$C$65,$A16,ข้อมูลดิบ!$B$2:$B$65,4)+COUNTIFS(ข้อมูลดิบ!$D$2:$D$65,$A16,ข้อมูลดิบ!$B$2:$B$65,4) -> 1 | F16: =COUNTIFS(ข้อมูลดิบ!$C$2:$C$65,$A16,ข้อมูลดิบ!$B$2:$B$65,5)+COUNTIFS(ข้อมูลดิบ!$D$2:$D$65,$A16,ข้อมูลดิบ!$B$2:$B$65,5) -> 1 | G16: =COUNTIFS(ข้อมูลดิบ!$C$2:$C$65,$A16,ข้อมูลดิบ!$B$2:$B$65,6)+COUNTIFS(ข้อมูลดิบ!$D$2:$D$65,$A16,ข้อมูลดิบ!$B$2:$B$65,6) -> 1 | H16: =COUNTIFS(ข้อมูลดิบ!$C$2:$C$65,$A16,ข้อมูลดิบ!$B$2:$B$65,7)+COUNTIFS(ข้อมูลดิบ!$D$2:$D$65,$A16,ข้อมูลดิบ!$B$2:$B$65,7) -> 1 | I16: =COUNTIFS(ข้อมูลดิบ!$C$2:$C$65,$A16,ข้อมูลดิบ!$B$2:$B$65,8)+COUNTIFS(ข้อมูลดิบ!$D$2:$D$65,$A16,ข้อมูลดิบ!$B$2:$B$65,8) -> 1 | K16: 6B | L16: =COUNTIFS(ข้อมูลดิบ!$C$2:$C$65,$K16,ข้อมูลดิบ!$A$2:$A$65,1)+COUNTIFS(ข้อมูลดิบ!$D$2:$D$65,$K16,ข้อมูลดิบ!$A$2:$A$65,1) -> 1 | M16: =COUNTIFS(ข้อมูลดิบ!$C$2:$C$65,$K16,ข้อมูลดิบ!$A$2:$A$65,2)+COUNTIFS(ข้อมูลดิบ!$D$2:$D$65,$K16,ข้อมูลดิบ!$A$2:$A$65,2) -> 1 | N16: =COUNTIFS(ข้อมูลดิบ!$C$2:$C$65,$K16,ข้อมูลดิบ!$A$2:$A$65,3)+COUNTIFS(ข้อมูลดิบ!$D$2:$D$65,$K16,ข้อมูลดิบ!$A$2:$A$65,3) -> 1 | O16: =COUNTIFS(ข้อมูลดิบ!$C$2:$C$65,$K16,ข้อมูลดิบ!$A$2:$A$65,4)+COUNTIFS(ข้อมูลดิบ!$D$2:$D$65,$K16,ข้อมูลดิบ!$A$2:$A$65,4) -> 1 | P16: =COUNTIFS(ข้อมูลดิบ!$C$2:$C$65,$K16,ข้อมูลดิบ!$A$2:$A$65,5)+COUNTIFS(ข้อมูลดิบ!$D$2:$D$65,$K16,ข้อมูลดิบ!$A$2:$A$65,5) -> 1 | Q16: =COUNTIFS(ข้อมูลดิบ!$C$2:$C$65,$K16,ข้อมูลดิบ!$A$2:$A$65,6)+COUNTIFS(ข้อมูลดิบ!$D$2:$D$65,$K16,ข้อมูลดิบ!$A$2:$A$65,6) -> 1 | R16: =COUNTIFS(ข้อมูลดิบ!$C$2:$C$65,$K16,ข้อมูลดิบ!$A$2:$A$65,7)+COUNTIFS(ข้อมูลดิบ!$D$2:$D$65,$K16,ข้อมูลดิบ!$A$2:$A$65,7) -> 1 | S16: =COUNTIFS(ข้อมูลดิบ!$C$2:$C$65,$K16,ข้อมูลดิบ!$A$2:$A$65,8)+COUNTIFS(ข้อมูลดิบ!$D$2:$D$65,$K16,ข้อมูลดิบ!$A$2:$A$65,8) -> 1
... A20: 8B | B20: =COUNTIFS(ข้อมูลดิบ!$C$2:$C$65,$A20,ข้อมูลดิบ!$B$2:$B$65,1)+COUNTIFS(ข้อมูลดิบ!$D$2:$D$65,$A20,ข้อมูลดิบ!$B$2:$B$65,1) -> 1 | C20: =COUNTIFS(ข้อมูลดิบ!$C$2:$C$65,$A20,ข้อมูลดิบ!$B$2:$B$65,2)+COUNTIFS(ข้อมูลดิบ!$D$2:$D$65,$A20,ข้อมูลดิบ!$B$2:$B$65,2) -> 1 | D20: =COUNTIFS(ข้อมูลดิบ!$C$2:$C$65,$A20,ข้อมูลดิบ!$B$2:$B$65,3)+COUNTIFS(ข้อมูลดิบ!$D$2:$D$65,$A20,ข้อมูลดิบ!$B$2:$B$65,3) -> 1 | E20: =COUNTIFS(ข้อมูลดิบ!$C$2:$C$65,$A20,ข้อมูลดิบ!$B$2:$B$65,4)+COUNTIFS(ข้อมูลดิบ!$D$2:$D$65,$A20,ข้อมูลดิบ!$B$2:$B$65,4) -> 1 | F20: =COUNTIFS(ข้อมูลดิบ!$C$2:$C$65,$A20,ข้อมูลดิบ!$B$2:$B$65,5)+COUNTIFS(ข้อมูลดิบ!$D$2:$D$65,$A20,ข้อมูลดิบ!$B$2:$B$65,5) -> 1 | G20: =COUNTIFS(ข้อมูลดิบ!$C$2:$C$65,$A20,ข้อมูลดิบ!$B$2:$B$65,6)+COUNTIFS(ข้อมูลดิบ!$D$2:$D$65,$A20,ข้อมูลดิบ!$B$2:$B$65,6) -> 1 | H20: =COUNTIFS(ข้อมูลดิบ!$C$2:$C$65,$A20,ข้อมูลดิบ!$B$2:$B$65,7)+COUNTIFS(ข้อมูลดิบ!$D$2:$D$65,$A20,ข้อมูลดิบ!$B$2:$B$65,7) -> 1 | I20: =COUNTIFS(ข้อมูลดิบ!$C$2:$C$65,$A20,ข้อมูลดิบ!$B$2:$B$65,8)+COUNTIFS(ข้อมูลดิบ!$D$2:$D$65,$A20,ข้อมูลดิบ!$B$2:$B$65,8) -> 1 | K20: 8B | L20: =COUNTIFS(ข้อมูลดิบ!$C$2:$C$65,$K20,ข้อมูลดิบ!$A$2:$A$65,1)+COUNTIFS(ข้อมูลดิบ!$D$2:$D$65,$K20,ข้อมูลดิบ!$A$2:$A$65,1) -> 1 | M20: =COUNTIFS(ข้อมูลดิบ!$C$2:$C$65,$K20,ข้อมูลดิบ!$A$2:$A$65,2)+COUNTIFS(ข้อมูลดิบ!$D$2:$D$65,$K20,ข้อมูลดิบ!$A$2:$A$65,2) -> 1 | N20: =COUNTIFS(ข้อมูลดิบ!$C$2:$C$65,$K20,ข้อมูลดิบ!$A$2:$A$65,3)+COUNTIFS(ข้อมูลดิบ!$D$2:$D$65,$K20,ข้อมูลดิบ!$A$2:$A$65,3) -> 1 | O20: =COUNTIFS(ข้อมูลดิบ!$C$2:$C$65,$K20,ข้อมูลดิบ!$A$2:$A$65,4)+COUNTIFS(ข้อมูลดิบ!$D$2:$D$65,$K20,ข้อมูลดิบ!$A$2:$A$65,4) -> 1 | P20: =COUNTIFS(ข้อมูลดิบ!$C$2:$C$65,$K20,ข้อมูลดิบ!$A$2:$A$65,5)+COUNTIFS(ข้อมูลดิบ!$D$2:$D$65,$K20,ข้อมูลดิบ!$A$2:$A$65,5) -> 1 | Q20: =COUNTIFS(ข้อมูลดิบ!$C$2:$C$65,$K20,ข้อมูลดิบ!$A$2:$A$65,6)+COUNTIFS(ข้อมูลดิบ!$D$2:$D$65,$K20,ข้อมูลดิบ!$A$2:$A$65,6) -> 1 | R20: =COUNTIFS(ข้อมูลดิบ!$C$2:$C$65,$K20,ข้อมูลดิบ!$A$2:$A$65,7)+COUNTIFS(ข้อมูลดิบ!$D$2:$D$65,$K20,ข้อมูลดิบ!$A$2:$A$65,7) -> 1 | S20: =COUNTIFS(ข้อมูลดิบ!$C$2:$C$65,$K20,ข้อมูลดิบ!$A$2:$A$65,8)+COUNTIFS(ข้อมูลดิบ!$D$2:$D$65,$K20,ข้อมูลดิบ!$A$2:$A$65,8) -> 1
A23: สรุปผลตรวจสอบ
A24: 1. ทุกทีมเข้าครบ 8 ฐาน ฐานละ 1 ครั้ง | D24: =IF(SUMPRODUCT(--(B5:I20<>1))=0,"ผ่าน","ไม่ผ่าน") -> ผ่าน
A25: 2. ทุกทีมลงเล่นครบทุกรอบ รอบละ 1 ครั้ง | D25: =IF(SUMPRODUCT(--(L5:S20<>1))=0,"ผ่าน","ไม่ผ่าน") -> ผ่าน
A26: 3. ไม่มีคู่แบทเทิลซ้ำกัน | D26: =IF(SUMPRODUCT(--(COUNTIF(ข้อมูลดิบ!$E$2:$E$65,ข้อมูลดิบ!$E$2:$E$65)<>1))=0,"ผ่าน","ไม่ผ่าน") -> ผ่าน
A27: 4. ไม่มีคู่ที่มาจากกลุ่มเดียวกัน | D27: =IF(SUM(ข้อมูลดิบ!$F$2:$F$65)=0,"ผ่าน","ไม่ผ่าน") -> ผ่าน
A28: 5. จำนวนคู่การแข่งขันทั้งหมด (ต้องเท่ากับ 64) | D28: =COUNTA(ข้อมูลดิบ!$C$2:$C$65) -> 64
